[2023-05-05 00:50:16,188] {taskinstance.py:1032} INFO - Dependencies all met for <TaskInstance: postgres_to_localfile.query_property_history manual__2023-05-05T00:50:13.681223+00:00 [queued]>
[2023-05-05 00:50:16,201] {taskinstance.py:1032} INFO - Dependencies all met for <TaskInstance: postgres_to_localfile.query_property_history manual__2023-05-05T00:50:13.681223+00:00 [queued]>
[2023-05-05 00:50:16,201] {taskinstance.py:1238} INFO - 
--------------------------------------------------------------------------------
[2023-05-05 00:50:16,202] {taskinstance.py:1239} INFO - Starting attempt 1 of 2
[2023-05-05 00:50:16,202] {taskinstance.py:1240} INFO - 
--------------------------------------------------------------------------------
[2023-05-05 00:50:16,218] {taskinstance.py:1259} INFO - Executing <Task(PostgresOperator): query_property_history> on 2023-05-05 00:50:13.681223+00:00
[2023-05-05 00:50:16,223] {standard_task_runner.py:52} INFO - Started process 3390 to run task
[2023-05-05 00:50:16,228] {standard_task_runner.py:76} INFO - Running: ['***', 'tasks', 'run', 'postgres_to_localfile', 'query_property_history', 'manual__2023-05-05T00:50:13.681223+00:00', '--job-id', '14', '--raw', '--subdir', 'DAGS_FOLDER/load_from_postgres.py', '--cfg-path', '/tmp/tmph0u0y_6h', '--error-file', '/tmp/tmpqujp8s4k']
[2023-05-05 00:50:16,229] {standard_task_runner.py:77} INFO - Job 14: Subtask query_property_history
[2023-05-05 00:50:16,364] {logging_mixin.py:109} INFO - Running <TaskInstance: postgres_to_localfile.query_property_history manual__2023-05-05T00:50:13.681223+00:00 [running]> on host ebd7ac88a2d5
[2023-05-05 00:50:16,453] {logging_mixin.py:109} WARNING - /usr/local/lib/python3.7/site-packages/***/models/xcom.py:323 SAWarning: TypeDecorator UtcDateTime(timezone=True) will not produce a cache key because the ``cache_ok`` attribute is not set to True.  This can have significant performance implications including some performance degradations in comparison to prior SQLAlchemy versions.  Set this attribute to True if this type object's state is safe to use in a cache key, or False to disable this warning. (Background on this error at: https://sqlalche.me/e/14/cprf)
[2023-05-05 00:50:16,477] {logging_mixin.py:109} WARNING - /usr/local/lib/python3.7/site-packages/***/models/renderedtifields.py:126 SAWarning: TypeDecorator UtcDateTime(timezone=True) will not produce a cache key because the ``cache_ok`` attribute is not set to True.  This can have significant performance implications including some performance degradations in comparison to prior SQLAlchemy versions.  Set this attribute to True if this type object's state is safe to use in a cache key, or False to disable this warning. (Background on this error at: https://sqlalche.me/e/14/cprf)
[2023-05-05 00:50:16,487] {logging_mixin.py:109} WARNING - /usr/local/lib/python3.7/site-packages/***/models/renderedtifields.py:162 SAWarning: Coercing Subquery object into a select() for use in IN(); please pass a select() construct explicitly
[2023-05-05 00:50:16,502] {logging_mixin.py:109} WARNING - /usr/local/lib/python3.7/site-packages/***/models/renderedtifields.py:163 SAWarning: TypeDecorator UtcDateTime(timezone=True) will not produce a cache key because the ``cache_ok`` attribute is not set to True.  This can have significant performance implications including some performance degradations in comparison to prior SQLAlchemy versions.  Set this attribute to True if this type object's state is safe to use in a cache key, or False to disable this warning. (Background on this error at: https://sqlalche.me/e/14/cprf)
[2023-05-05 00:50:16,510] {taskinstance.py:1426} INFO - Exporting the following env vars:
AIRFLOW_CTX_DAG_EMAIL=***@example.com
AIRFLOW_CTX_DAG_OWNER=***
AIRFLOW_CTX_DAG_ID=postgres_to_localfile
AIRFLOW_CTX_TASK_ID=query_property_history
AIRFLOW_CTX_EXECUTION_DATE=2023-05-05T00:50:13.681223+00:00
AIRFLOW_CTX_DAG_RUN_ID=manual__2023-05-05T00:50:13.681223+00:00
[2023-05-05 00:50:16,529] {base.py:79} INFO - Using connection to: id: postgres_uibakery. Host: psql-mock-database-cloud.postgres.database.azure.com, Port: 5432, Schema: booking1683211418712chwclaffprnvpgex, Login: yiauuwwzjsorextafdlhlncs%40psql-mock-database-cloud, Password: ***, extra: {}
[2023-05-05 00:50:17,964] {taskinstance.py:1700} ERROR - Task failed with exception
Traceback (most recent call last):
  File "/usr/local/lib/python3.7/site-packages/airflow/models/taskinstance.py", line 1329, in _run_raw_task
    self._execute_task_with_callbacks(context)
  File "/usr/local/lib/python3.7/site-packages/airflow/models/taskinstance.py", line 1455, in _execute_task_with_callbacks
    result = self._execute_task(context, self.task)
  File "/usr/local/lib/python3.7/site-packages/airflow/models/taskinstance.py", line 1511, in _execute_task
    result = execute_callable(context=context)
  File "/usr/local/lib/python3.7/site-packages/airflow/providers/postgres/operators/postgres.py", line 94, in execute
    self.hook.run(self.sql, self.autocommit, parameters=self.parameters)
  File "/usr/local/lib/python3.7/site-packages/airflow/providers/common/sql/hooks/sql.py", line 342, in run
    with closing(self.get_conn()) as conn:
  File "/usr/local/lib/python3.7/site-packages/airflow/providers/postgres/hooks/postgres.py", line 115, in get_conn
    self.conn = psycopg2.connect(**conn_args)
  File "/usr/local/lib/python3.7/site-packages/psycopg2/__init__.py", line 122, in connect
    conn = _connect(dsn, connection_factory=connection_factory, **kwasync)
psycopg2.OperationalError: FATAL:  Invalid Username specified. Please check the Username and retry connection. The Username should be in <username@hostname> format.
FATAL:  Invalid Username specified. Please check the Username and retry connection. The Username should be in <username@hostname> format.

[2023-05-05 00:50:17,985] {taskinstance.py:1277} INFO - Marking task as UP_FOR_RETRY. dag_id=postgres_to_localfile, task_id=query_property_history, execution_date=20230505T005013, start_date=20230505T005016, end_date=20230505T005017
[2023-05-05 00:50:18,004] {standard_task_runner.py:92} ERROR - Failed to execute job 14 for task query_property_history
Traceback (most recent call last):
  File "/usr/local/lib/python3.7/site-packages/airflow/task/task_runner/standard_task_runner.py", line 85, in _start_by_fork
    args.func(args, dag=self.dag)
  File "/usr/local/lib/python3.7/site-packages/airflow/cli/cli_parser.py", line 48, in command
    return func(*args, **kwargs)
  File "/usr/local/lib/python3.7/site-packages/airflow/utils/cli.py", line 92, in wrapper
    return f(*args, **kwargs)
  File "/usr/local/lib/python3.7/site-packages/airflow/cli/commands/task_command.py", line 298, in task_run
    _run_task_by_selected_method(args, dag, ti)
  File "/usr/local/lib/python3.7/site-packages/airflow/cli/commands/task_command.py", line 107, in _run_task_by_selected_method
    _run_raw_task(args, ti)
  File "/usr/local/lib/python3.7/site-packages/airflow/cli/commands/task_command.py", line 184, in _run_raw_task
    error_file=args.error_file,
  File "/usr/local/lib/python3.7/site-packages/airflow/utils/session.py", line 70, in wrapper
    return func(*args, session=session, **kwargs)
  File "/usr/local/lib/python3.7/site-packages/airflow/models/taskinstance.py", line 1329, in _run_raw_task
    self._execute_task_with_callbacks(context)
  File "/usr/local/lib/python3.7/site-packages/airflow/models/taskinstance.py", line 1455, in _execute_task_with_callbacks
    result = self._execute_task(context, self.task)
  File "/usr/local/lib/python3.7/site-packages/airflow/models/taskinstance.py", line 1511, in _execute_task
    result = execute_callable(context=context)
  File "/usr/local/lib/python3.7/site-packages/airflow/providers/postgres/operators/postgres.py", line 94, in execute
    self.hook.run(self.sql, self.autocommit, parameters=self.parameters)
  File "/usr/local/lib/python3.7/site-packages/airflow/providers/common/sql/hooks/sql.py", line 342, in run
    with closing(self.get_conn()) as conn:
  File "/usr/local/lib/python3.7/site-packages/airflow/providers/postgres/hooks/postgres.py", line 115, in get_conn
    self.conn = psycopg2.connect(**conn_args)
  File "/usr/local/lib/python3.7/site-packages/psycopg2/__init__.py", line 122, in connect
    conn = _connect(dsn, connection_factory=connection_factory, **kwasync)
psycopg2.OperationalError: FATAL:  Invalid Username specified. Please check the Username and retry connection. The Username should be in <username@hostname> format.
FATAL:  Invalid Username specified. Please check the Username and retry connection. The Username should be in <username@hostname> format.

[2023-05-05 00:50:18,021] {local_task_job.py:154} INFO - Task exited with return code 1
[2023-05-05 00:50:18,108] {local_task_job.py:264} INFO - 0 downstream tasks scheduled from follow-on schedule check
[2023-05-05 00:50:18,111] {logging_mixin.py:109} WARNING - /usr/local/lib/python3.7/site-packages/***/models/dag.py:1076 SADeprecationWarning: Query.value() is deprecated and will be removed in a future release.  Please use Query.with_entities() in combination with Query.scalar() (deprecated since: 1.4)
[2023-05-05 00:50:18,113] {logging_mixin.py:109} WARNING - /usr/local/lib/python3.7/site-packages/***/models/dag.py:1076 SADeprecationWarning: Query.values() is deprecated and will be removed in a future release.  Please use Query.with_entities() (deprecated since: 1.4)
